Workbook

Sheet DASHBOARD
A1: Macro Regime-to-Portfolio Decision Framework
A2: ="As of: "&TEXT(_DASH_DATA!B2,"yyyy-mm-dd")&" | Data: FRED | Tool: Python, Excel | Frequency: Weekly" -> As of: 2026-10-09 | Data: FRED | Tool: Python, Excel | Frequency: Weekly
A4: Executive Summary | I4: Portfolio Stance
A5: ="Portfolio: Equity "&_DASH_DATA!B11&", Duration "&_DASH_DATA!B13&", Cash "&_DASH_DATA!B15&", TIPS "&_DASH_DATA!B17 -> Portfolio: Equity Neutral, Duration Neutral, Cash Overweight, TIPS Neutral | I5: Asset | K5: Stance
A6: ="Risk Appetite: "&_DASH_DATA!B3&" — "&IF(_DASH_DATA!B3="Risk-On","no broad risk-stress signals are active",IF(_DASH_DATA!B3="Neutral","some risk-stress signals are active, but not broad-based",IF(_DASH_DATA!B3="Risk-Off","broad risk-stress signals are active","insufficient signal clarity"))) -> Risk Appetite: Neutral — some risk-stress signals are active, but not broad-based | I6: Equity | K6: =_DASH_DATA!B11 -> Neutral
A7: ="Rates & Inflation: "&_DASH_DATA!B6&" — "&IF(_DASH_DATA!B6="Regime 1","rate pressure elevated and inflation concern elevated",IF(_DASH_DATA!B6="Regime 2","rate pressure elevated, inflation concern not elevated",IF(_DASH_DATA!B6="Regime 3","rate pressure not elevated, inflation concern elevated",IF(_DASH_DATA!B6="Regime 4","rate pressure not elevated and inflation concern not elevated","insufficient signal clarity")))) -> Rates & Inflation: Regime 2 — rate pressure elevated, inflation concern not elevated | I7: Nominal Treasury Duration | K7: =_DASH_DATA!B13 -> Neutral
A8: ="Risk Trend: "&_DASH_DATA!B5&" | Real Yield Tightening: "&_DASH_DATA!B9&"" -> Risk Trend: Deteriorating | Real Yield Tightening: ON | I8: Cash / T-bills | K8: =_DASH_DATA!B15 -> Overweight
A9: ="QA Checks: "&IF(ISNUMBER(SEARCH("FAIL",_DASH_DATA!B19)),"Failed",IF(ISNUMBER(SEARCH("WARN",_DASH_DATA!B19)),"Warning","Passed"))&" | Signals are rule-based weekly indicators, not return forecasts." -> QA Checks: Passed | Signals are rule-based weekly indicators, not return forecasts. | I9: TIPS (Inflation Protection) | K9: =_DASH_DATA!B17 -> Neutral
A10: Risk Appetite Score Map: 0 = Risk-On, 1–2 = Neutral, 3–4 = Risk-Off
A11: Regime Map: 1 = Rate + Inflation | 2 = Rate only | 3 = Inflation only | 4 = No pressure
A13: Risk Appetite Score History | I13: Rates & Inflation Regime Timeline
A28: ="Latest observation: "&TEXT(_DASH_DATA!D105,"yyyy-mm-dd")&", Score "&_DASH_DATA!H105 -> Latest observation: 2026-10-09, Score 2 | I28: Regime Map: 1 = Rate + Inflation | 2 = Rate only | 3 = Inflation only | 4 = No pressure
A30: Real Yield Tightening Context | I30: Rate Pressure Context
I44: P80 = rate-pressure threshold; P20 = context only.
A45: P80 = tightening threshold; P20 = context only.
A47: Inflation Compensation Context | I47: Yield Curve Context
A62: P80 = inflation-concern threshold; P20 = context only. | I62: Below zero indicates an inverted yield curve.
A64: Stress-event Snapshot / Method Notes
A65: This dashboard monitors a rule-based macro-regime framework. Risk Appetite tracks market stress; Rates & Inflation Regime tracks rate pressure and inflation concern. Signals are weekly indicators, not return forecasts.

Sheet PDF_MEMO_1
A1: =_PDF_DATA!C2 -> Macro Regime-to-Portfolio Decision Framework
A2: =IF(_PDF_DATA!C3="","Weekly Research Memo | As of: [As of Date] | Data: FRED | Tool: Python, Excel | Frequency: Weekly",_PDF_DATA!C3) -> Weekly Research Memo | As of: 2026-10-09 | Data: FRED | Tool: Python, Excel | Frequency: Weekly
A4: Executive Summary
A5: =IF(_PDF_DATA!R15="","",_PDF_DATA!R15) -> Portfolio | C5: =IF(_PDF_DATA!S15="","",_PDF_DATA!S15) -> Equity Neutral, Duration Neutral, Cash Overweight, TIPS Neutral
A6: =IF(_PDF_DATA!R16="","",_PDF_DATA!R16) -> Risk Appetite | C6: =IF(_PDF_DATA!S16="","",_PDF_DATA!S16) -> Neutral — risk conditions are no longer cleanly Risk-On.
A7: =IF(_PDF_DATA!R17="","",_PDF_DATA!R17) -> Rates & Inflation | C7: =IF(_PDF_DATA!S17="","",_PDF_DATA!S17) -> Rate Pressure Only — inflation concern is not elevated.
A8: =IF(_PDF_DATA!R18="","",_PDF_DATA!R18) -> Real Yield | C8: =IF(_PDF_DATA!S18="","",_PDF_DATA!S18) -> Tightening ON — aggressive equity and duration overweights remain constrained.
A9: =IF(_PDF_DATA!R19="","",_PDF_DATA!R19) -> Data Quality | C9: =IF(_PDF_DATA!S19="","",_PDF_DATA!S19) -> Pass.
A11: Current Signal Snapshot | G11: Portfolio Stance
A12: Risk Appetite | C12: =IF(_PDF_DATA!C5="","",_PDF_DATA!C5) -> Neutral | G12: Asset Class | I12: Stance
A13: Risk Appetite Score | C13: =IF(_PDF_DATA!C6="","",_PDF_DATA!C6&" of 4") -> 2 of 4 | G13: =IF(_PDF_DATA!E2="","",_PDF_DATA!E2) -> Equity | I13: =IF(_PDF_DATA!F2="","",_PDF_DATA!F2) -> Neutral
A14: Direction of Travel | C14: =IF(_PDF_DATA!C7="","",_PDF_DATA!C7) -> Deteriorating | G14: Treasury Duration | I14: =IF(_PDF_DATA!F3="","",_PDF_DATA!F3) -> Neutral
A15: Rates & Inflation | C15: =IF(_PDF_DATA!C16="","",_PDF_DATA!C16) -> Rate Pressure Only | G15: Cash / T-bills | I15: =IF(_PDF_DATA!F4="","",_PDF_DATA!F4) -> Overweight
A16: Rate Pressure | C16: =IF(_PDF_DATA!C10="","",_PDF_DATA!C10) -> ON | G16: TIPS (Inflation Protection) | I16: =IF(_PDF_DATA!F5="","",_PDF_DATA!F5) -> Neutral
A17: Inflation Concern | C17: =IF(_PDF_DATA!C11="","",_PDF_DATA!C11) -> OFF | G17: =IF(_PDF_DATA!G6="","","Note: "&_PDF_DATA!G6) -> Note: Equity and duration overweights are capped while Real Yield Tightening remains ON.
A18: Real Yield Tightening | C18: =IF(_PDF_DATA!C12="","",_PDF_DATA!C12) -> ON
A19: Data Quality | C19: =IF(_PDF_DATA!C14="","",_PDF_DATA!C14) -> Pass | G19: Stances are qualitative directional signals and not optimized portfolio weights.
A20: Risk Appetite Score Map: 0 = Risk-On, 1–2 = Neutral, 3–4 = Risk-Off
A21: Rates & Inflation Regime: 1 = Rate + Inflation Pressure | 2 = Rate Pressure Only | 3 = Inflation Concern Only | 4 = No Pressure
A23: Decision Rationale
A24: =IF(_PDF_DATA!R21="","",_PDF_DATA!R21) -> Risk Appetite | C24: =IF(_PDF_DATA!S21="","",_PDF_DATA!S21) -> Risk appetite deterioration argues against adding aggressive equity risk.
A25: =IF(_PDF_DATA!R22="","",_PDF_DATA!R22) -> Rates & Inflation | C25: =IF(_PDF_DATA!S22="","",_PDF_DATA!S22) -> Active rate pressure keeps duration neutral; inflation concern is not elevated.
A26: =IF(_PDF_DATA!R23="","",_PDF_DATA!R23) -> Real Yield | C26: =IF(_PDF_DATA!S23="","",_PDF_DATA!S23) -> Real Yield Tightening caps aggressive equity and duration overweight positions.
A27: =IF(_PDF_DATA!R24="","",_PDF_DATA!R24) -> Cash | C27: =IF(_PDF_DATA!S24="","",_PDF_DATA!S24) -> Cash remains overweight as a liquidity buffer while rate pressure and real-yield tightening remain active.
A29: What Changed
A30: =IF(_PDF_DATA!R26="","",_PDF_DATA!R26) -> Risk Appetite | C30: =IF(_PDF_DATA!S26="","",_PDF_DATA!S26) -> Remained Neutral.
A31: =IF(_PDF_DATA!R27="","",_PDF_DATA!R27) -> Risk Appetite Score | C31: =IF(_PDF_DATA!S27="","",_PDF_DATA!S27) -> Remained 2 of 4.
A32: =IF(_PDF_DATA!R28="","",_PDF_DATA!R28) -> Rates & Inflation | C32: =IF(_PDF_DATA!S28="","",_PDF_DATA!S28) -> Shifted from Rate + Inflation Pressure to Rate Pressure Only as Inflation Concern turned OFF.
A33: =IF(_PDF_DATA!R29="","",_PDF_DATA!R29) -> Portfolio | C33: =IF(_PDF_DATA!S29="","",_PDF_DATA!S29) -> Shifted to Equity Neutral, Duration Neutral, Cash Overweight, TIPS Neutral.
A35: Next Triggers
A36: =IF(_PDF_DATA!R31="","",_PDF_DATA!R31) -> Risk Appetite | C36: =IF(_PDF_DATA!S31="","",_PDF_DATA!S31) -> A Risk Appetite Score of 3+ would shift the framework to Risk-Off; a score of 0 would restore Risk-On.
A37: =IF(_PDF_DATA!R32="","",_PDF_DATA!R32) -> Rates & Inflation | C37: =IF(_PDF_DATA!S32="","",_PDF_DATA!S32) -> Inflation concern turning ON would shift the backdrop to Rate + Inflation Pressure.
A38: =IF(_PDF_DATA!R33="","",_PDF_DATA!R33) -> Real Yield | C38: =IF(_PDF_DATA!S33="","",_PDF_DATA!S33) -> While Real Yield Tightening remains ON, aggressive equity and duration overweights remain constrained.
A39: =IF(_PDF_DATA!R34="","",_PDF_DATA!R34) -> Portfolio | C39: =IF(_PDF_DATA!S34="","",_PDF_DATA!S34) -> Further risk deterioration would justify a more defensive allocation stance.
A41: Signals are regime indicators, not return forecasts.
A42: Inputs include HY OAS, NFCI, VIX, Initial Claims, 10Y Treasury yield, breakeven inflation, and 10Y real yield.

Sheet PDF_MEMO_2
A1: =_PDF_DATA!C2 -> Macro Regime-to-Portfolio Decision Framework
A2: Supporting Evidence & Framework Audit | Driver Detail | Rule Map | Stress Event Audit
A4: Driver Detail & Signal Evidence
A5: =IF(_PDF_DATA!V1="","",_PDF_DATA!V1) -> Channel | C5: =IF(_PDF_DATA!W1="","",_PDF_DATA!W1) -> Indicator | E5: =IF(_PDF_DATA!X1="","",_PDF_DATA!X1) -> Previous | F5: =IF(_PDF_DATA!Y1="","",_PDF_DATA!Y1) -> Current | G5: =IF(_PDF_DATA!Z1="","",_PDF_DATA!Z1) -> Interpretation
A6: =IF(_PDF_DATA!V2="","",_PDF_DATA!V2) -> Credit | C6: =IF(_PDF_DATA!W2="","",_PDF_DATA!W2) -> HY OAS | E6: =IF(_PDF_DATA!X2="","",_PDF_DATA!X2) -> ON (L+T) | F6: =IF(_PDF_DATA!Y2="","",_PDF_DATA!Y2) -> ON (L+T) | G6: =IF(_PDF_DATA!Z2="","",_PDF_DATA!Z2) -> Credit stress remains active; level and trend confirmed.
A7: =IF(_PDF_DATA!V3="","",_PDF_DATA!V3) -> Financial Conditions | C7: =IF(_PDF_DATA!W3="","",_PDF_DATA!W3) -> NFCI | E7: =IF(_PDF_DATA!X3="","",_PDF_DATA!X3) -> ON | F7: =IF(_PDF_DATA!Y3="","",_PDF_DATA!Y3) -> ON | G7: =IF(_PDF_DATA!Z3="","",_PDF_DATA!Z3) -> Financial conditions remain stressed.
A8: =IF(_PDF_DATA!V4="","",_PDF_DATA!V4) -> Volatility | C8: =IF(_PDF_DATA!W4="","",_PDF_DATA!W4) -> VIX | E8: =IF(_PDF_DATA!X4="","",_PDF_DATA!X4) -> OFF | F8: =IF(_PDF_DATA!Y4="","",_PDF_DATA!Y4) -> OFF | G8: =IF(_PDF_DATA!Z4="","",_PDF_DATA!Z4) -> Volatility stress remains inactive.
A9: =IF(_PDF_DATA!V5="","",_PDF_DATA!V5) -> Labor Market | C9: =IF(_PDF_DATA!W5="","",_PDF_DATA!W5) -> Initial Claims | E9: =IF(_PDF_DATA!X5="","",_PDF_DATA!X5) -> OFF | F9: =IF(_PDF_DATA!Y5="","",_PDF_DATA!Y5) -> OFF | G9: =IF(_PDF_DATA!Z5="","",_PDF_DATA!Z5) -> Labor-market stress remains inactive.
A10: =IF(_PDF_DATA!V6="","",_PDF_DATA!V6) -> Rates | C10: =IF(_PDF_DATA!W6="","",_PDF_DATA!W6) -> Rate Pressure | E10: =IF(_PDF_DATA!X6="","",_PDF_DATA!X6) -> ON (L+T) | F10: =IF(_PDF_DATA!Y6="","",_PDF_DATA!Y6) -> ON (L+T) | G10: =IF(_PDF_DATA!Z6="","",_PDF_DATA!Z6) -> Rate pressure remains active; level and trend confirmed.
A12: =IF(_PDF_DATA!V7="","",_PDF_DATA!V7) -> Inflation | C12: =IF(_PDF_DATA!W7="","",_PDF_DATA!W7) -> Inflation Concern | E12: =IF(_PDF_DATA!X7="","",_PDF_DATA!X7) -> ON (Trend) | F12: =IF(_PDF_DATA!Y7="","",_PDF_DATA!Y7) -> OFF | G12: =IF(_PDF_DATA!Z7="","",_PDF_DATA!Z7) -> Inflation concern remains inactive.
A14: =IF(_PDF_DATA!V8="","",_PDF_DATA!V8) -> Real Yield | C14: =IF(_PDF_DATA!W8="","",_PDF_DATA!W8) -> Real Yield Tightening | E14: =IF(_PDF_DATA!X8="","",_PDF_DATA!X8) -> ON (L+T) | F14: =IF(_PDF_DATA!Y8="","",_PDF_DATA!Y8) -> ON (L+T) | G14: =IF(_PDF_DATA!Z8="","",_PDF_DATA!Z8) -> Real-yield tightening remains active; level and trend confirmed.
A16: Driver flags explain regime evidence, not return forecasts. | G16: Note: L+T = Level + Trend.
A18: Risk Appetite — Historical Signal Evidence | G18: Rates & Inflation — Historical Regime Evidence
A30: Risk Appetite Engine | G30: Rates & Inflation Regime Matrix
A31: =IF(_PDF_DATA!U12="","",_PDF_DATA!U12) -> Indicator | B31: =IF(_PDF_DATA!W12="","",_PDF_DATA!W12) -> Trigger Rule | E31: ="Score" -> Score | G31: Rate | H31: Inflation | I31: Regime | J31: Display Label
A32: =IF(_PDF_DATA!U13="","",_PDF_DATA!U13) -> HY OAS | B32: =IF(_PDF_DATA!W13="","",_PDF_DATA!W13) -> Level > rolling P80 OR positive 4W change | E32: ="+1" -> +1 | G32: =IF(_PDF_DATA!AB16="","",_PDF_DATA!AB16) -> ON | H32: =IF(_PDF_DATA!AB16="","",_PDF_DATA!AB16) -> ON | I32: 1 | J32: =IF(_PDF_DATA!AE16="","",_PDF_DATA!AE16) -> Rate + Inflation Pressure
A33: =IF(_PDF_DATA!U14="","",_PDF_DATA!U14) -> NFCI | B33: =IF(_PDF_DATA!W14="","",_PDF_DATA!W14) -> Level > rolling P80 | E33: ="+1" -> +1 | G33: =IF(_PDF_DATA!AB17="","",_PDF_DATA!AB17) -> ON | H33: =IF(_PDF_DATA!AC17="","",_PDF_DATA!AC17) -> OFF | I33: 2 | J33: =IF(_PDF_DATA!AE17="","",_PDF_DATA!AE17) -> Rate Pressure Only
A34: =IF(_PDF_DATA!U15="","",_PDF_DATA!U15) -> VIX | B34: =IF(_PDF_DATA!W15="","",_PDF_DATA!W15) -> Level > rolling P80 | E34: ="+1" -> +1 | G34: =IF(_PDF_DATA!AB18="","",_PDF_DATA!AB18) -> OFF | H34: =IF(_PDF_DATA!AC18="","",_PDF_DATA!AC18) -> ON | I34: 3 | J34: =IF(_PDF_DATA!AE18="","",_PDF_DATA!AE18) -> Inflation Concern Only
A35: =IF(_PDF_DATA!U16="","",_PDF_DATA!U16) -> Initial Claims | B35: =IF(_PDF_DATA!W16="","",_PDF_DATA!W16) -> Level > rolling P80 | E35: ="+1" -> +1 | G35: =IF(_PDF_DATA!AB19="","",_PDF_DATA!AB19) -> OFF | H35: =IF(_PDF_DATA!AC19="","",_PDF_DATA!AC19) -> OFF | I35: 4 | J35: =IF(_PDF_DATA!AE19="","",_PDF_DATA!AE19) -> No Rate / Inflation Pressure
A36: Risk Appetite Score Map: 0 = Risk-On, 1–2 = Neutral, 3–4 = Risk-Off
A38: Rates & Inflation Engine
A39: Component | C39: Trigger Rule | F39: Role
A40: =IF(_PDF_DATA!AA13="","",_PDF_DATA!AA13) -> 10Y Treasury Yield | C40: ="P80 level OR positive 4W change" -> P80 level OR positive 4W change | F40: ="Rate Pressure" -> Rate Pressure
A41: =IF(_PDF_DATA!AA14="","",_PDF_DATA!AA14) -> 10Y Breakeven Inflation | C41: ="P80 level OR positive 4W change" -> P80 level OR positive 4W change | F41: ="Inflation Concern" -> Inflation Concern
A42: =IF(_PDF_DATA!AA15="","",_PDF_DATA!AA15) -> 10Y Real Yield | C42: ="P80 level OR positive 4W change" -> P80 level OR positive 4W change | F42: ="Portfolio constraint" -> Portfolio constraint
A44: Historical Regime Recognition
A45: Event | D45: Regime Recognition | F45: Recognition Timing | H45: Peak Risk Score | J45: Peak R&I Regime
A46: =IF(_PDF_DATA!AT2="","",_PDF_DATA!AT2) -> Global Financial Crisis | D46: =IF(_PDF_DATA!AU2="","",_PDF_DATA!AU2) -> Recognized | F46: =IF(_PDF_DATA!AV2="","",_PDF_DATA!AV2) -> 0 | H46: =IF(_PDF_DATA!AW2="","",_PDF_DATA!AW2) -> 4 | J46: =IF(_PDF_DATA!AX2="","",_PDF_DATA!AX2) -> R4
A47: =IF(_PDF_DATA!AT3="","",_PDF_DATA!AT3) -> COVID Shock | D47: =IF(_PDF_DATA!AU2="","",_PDF_DATA!AU3) -> Recognized | F47: =IF(_PDF_DATA!AV2="","",_PDF_DATA!AV3) -> 0 | H47: =IF(_PDF_DATA!AW2="","",_PDF_DATA!AW3) -> 4 | J47: =IF(_PDF_DATA!AX2="","",_PDF_DATA!AX3) -> R4
A48: =IF(_PDF_DATA!AT4="","",_PDF_DATA!AT4) -> 2022 Inflation / Rates Shock | D48: =IF(_PDF_DATA!AU2="","",_PDF_DATA!AU4) -> Recognized | F48: =IF(_PDF_DATA!AV2="","",_PDF_DATA!AV4) -> 0 | H48: =IF(_PDF_DATA!AW2="","",_PDF_DATA!AW4) -> 1 | J48: =IF(_PDF_DATA!AX2="","",_PDF_DATA!AX4) -> R1
A49: =IF(_PDF_DATA!AT5="","",_PDF_DATA!AT5) -> 2023 Regional Bank Stress | D49: =IF(_PDF_DATA!AU2="","",_PDF_DATA!AU5) -> Recognized | F49: =IF(_PDF_DATA!AV2="","",_PDF_DATA!AV5) -> 0 | H49: =IF(_PDF_DATA!AW2="","",_PDF_DATA!AW5) -> 3 | J49: =IF(_PDF_DATA!AX2="","",_PDF_DATA!AX5) -> R4
A50: Case results are regime diagnostics, not forecasts or return backtests. Timing 0 may reflect pre-existing stress. R1–R4 denote Rates & Inflation regimes.

Sheet Portfolio Router
A1: As-of Date | B1: Portfolio Router Valid | C1: Risk Appetite Regime | D1: Risk Appetite Score | E1: Rates & Inflation Regime | F1: Real_Yield_Tightening | G1: Equity_Stance | H1: Duration_Stance | I1: Cash_Stance | J1: TIPS_Stance | K1: Equity_Band | L1: Duration_Band | M1: Cash_Band | N1: TIPS_Band | O1: Portfolio Adjustments | P1: Portfolio Notes
A2: 22651 | B2: FALSE | C2: Insufficient Data | E2: Insufficient Data | G2: Insufficient Data | H2: Insufficient Data | I2: Insufficient Data | J2: Insufficient Data | K2: N/A | L2: N/A | M2: N/A | N2: N/A | O2: Insufficient Data | P2: Insufficient data to run Portfolio Router.
A3: 22658 | B3: FALSE | C3: Insufficient Data | E3: Insufficient Data | G3: Insufficient Data | H3: Insufficient Data | I3: Insufficient Data | J3: Insufficient Data | K3: N/A | L3: N/A | M3: N/A | N3: N/A | O3: Insufficient Data | P3: Insufficient data to run Portfolio Router.
A4: 22665 | B4: FALSE | C4: Insufficient Data | E4: Insufficient Data | G4: Insufficient Data | H4: Insufficient Data | I4: Insufficient Data | J4: Insufficient Data | K4: N/A | L4: N/A | M4: N/A | N4: N/A | O4: Insufficient Data | P4: Insufficient data to run Portfolio Router.
A5: 22672 | B5: FALSE | C5: Insufficient Data | E5: Insufficient Data | G5: Insufficient Data | H5: Insufficient Data | I5: Insufficient Data | J5: Insufficient Data | K5: N/A | L5: N/A | M5: N/A | N5: N/A | O5: Insufficient Data | P5: Insufficient data to run Portfolio Router.
A6: 22679 | B6: FALSE | C6: Insufficient Data | E6: Insufficient Data | G6: Insufficient Data | H6: Insufficient Data | I6: Insufficient Data | J6: Insufficient Data | K6: N/A | L6: N/A | M6: N/A | N6: N/A | O6: Insufficient Data | P6: Insufficient data to run Portfolio Router.
A7: 22686 | B7: FALSE | C7: Insufficient Data | E7: Insufficient Data | G7: Insufficient Data | H7: Insufficient Data | I7: Insufficient Data | J7: Insufficient Data | K7: N/A | L7: N/A | M7: N/A | N7: N/A | O7: Insufficient Data | P7: Insufficient data to run Portfolio Router.
A8: 22693 | B8: FALSE | C8: Insufficient Data | E8: Insufficient Data | G8: Insufficient Data | H8: Insufficient Data | I8: Insufficient Data | J8: Insufficient Data | K8: N/A | L8: N/A | M8: N/A | N8: N/A | O8: Insufficient Data | P8: Insufficient data to run Portfolio Router.
A9: 22700 | B9: FALSE | C9: Insufficient Data | E9: Insufficient Data | G9: Insufficient Data | H9: Insufficient Data | I9: Insufficient Data | J9: Insufficient Data | K9: N/A | L9: N/A | M9: N/A | N9: N/A | O9: Insufficient Data | P9: Insufficient data to run Portfolio Router.
A10: 22707 | B10: FALSE | C10: Insufficient Data | E10: Insufficient Data | G10: Insufficient Data | H10: Insufficient Data | I10: Insufficient Data | J10: Insufficient Data | K10: N/A | L10: N/A | M10: N/A | N10: N/A | O10: Insufficient Data | P10: Insufficient data to run Portfolio Router.
A11: 22714 | B11: FALSE | C11: Insufficient Data | E11: Insufficient Data | G11: Insufficient Data | H11: Insufficient Data | I11: Insufficient Data | J11: Insufficient Data | K11: N/A | L11: N/A | M11: N/A | N11: N/A | O11: Insufficient Data | P11: Insufficient data to run Portfolio Router.
A12: 22721 | B12: FALSE | C12: Insufficient Data | E12: Insufficient Data | G12: Insufficient Data | H12: Insufficient Data | I12: Insufficient Data | J12: Insufficient Data | K12: N/A | L12: N/A | M12: N/A | N12: N/A | O12: Insufficient Data | P12: Insufficient data to run Portfolio Router.
A13: 22728 | B13: FALSE | C13: Insufficient Data | E13: Insufficient Data | G13: Insufficient Data | H13: Insufficient Data | I13: Insufficient Data | J13: Insufficient Data | K13: N/A | L13: N/A | M13: N/A | N13: N/A | O13: Insufficient Data | P13: Insufficient data to run Portfolio Router.
... A2295: 38702 | B2295: FALSE | C2295: Insufficient Data | E2295: Regime 4 | G2295: Insufficient Data | H2295: Insufficient Data | I2295: Insufficient Data | J2295: Insufficient Data | K2295: N/A | L2295: N/A | M2295: N/A | N2295: N/A | O2295: Insufficient Data | P2295: Insufficient data to run Portfolio Router.
A2296: 38709 | B2296: TRUE | C2296: Neutral | D2296: 1 | E2296: Regime 4 | F2296: TRUE | G2296: Neutral | H2296: Neutral | I2296: Neutral | J2296: Neutral | K2296: 45-55% | L2296: 25-35% | M2296: 10-20% | N2296: 3-7% | O2296: Duration Overweight capped to Neutral due to Real Yield Tightening. | P2296: Duration Overweight capped to Neutral due to Real Yield Tightening. Final stance reflects Real Yield Tightening modifier.
A2297: 38716 | B2297: TRUE | C2297: Neutral | D2297: 2 | E2297: Regime 4 | F2297: TRUE | G2297: Neutral | H2297: Neutral | I2297: Neutral | J2297: Neutral | K2297: 45-55% | L2297: 25-35% | M2297: 10-20% | N2297: 3-7% | O2297: Duration Overweight capped to Neutral due to Real Yield Tightening. | P2297: Duration Overweight capped to Neutral due to Real Yield Tightening. Final stance reflects Real Yield Tightening modifier.
A2298: 38723 | B2298: TRUE | C2298: Neutral | D2298: 2 | E2298: Regime 4 | F2298: TRUE | G2298: Neutral | H2298: Neutral | I2298: Neutral | J2298: Neutral | K2298: 45-55% | L2298: 25-35% | M2298: 10-20% | N2298: 3-7% | O2298: Duration Overweight capped to Neutral due to Real Yield Tightening. | P2298: Duration Overweight capped to Neutral due to Real Yield Tightening. Final stance reflects Real Yield Tightening modifier.
A2299: 38730 | B2299: TRUE | C2299: Risk-On | D2299: 0 | E2299: Regime 3 | F2299: FALSE | G2299: Overweight | H2299: Neutral | I2299: Neutral | J2299: Overweight | K2299: 60-70% | L2299: 25-35% | M2299: 10-20% | N2299: 8-15% | O2299: None | P2299: Real Yield Tightening is OFF; base Portfolio Router stance is unchanged. Final stance matches base Portfolio Router stance.
A2300: 38737 | B2300: TRUE | C2300: Neutral | D2300: 1 | E2300: Regime 3 | F2300: FALSE | G2300: Neutral | H2300: Neutral | I2300: Neutral | J2300: Overweight | K2300: 45-55% | L2300: 25-35% | M2300: 10-20% | N2300: 8-15% | O2300: None | P2300: Real Yield Tightening is OFF; base Portfolio Router stance is unchanged. Final stance matches base Portfolio Router stance.
A2301: 38744 | B2301: TRUE | C2301: Risk-On | D2301: 0 | E2301: Regime 1 | F2301: TRUE | G2301: Neutral | H2301: Underweight | I2301: Overweight | J2301: Overweight | K2301: 45-55% | L2301: 10-20% | M2301: 25-35% | N2301: 8-15% | O2301: None | P2301: Real Yield Tightening is ON, but no Equity or Duration Overweight stance needed to be capped. Final stance matches base Portfolio Router stance.
A2302: 38751 | B2302: TRUE | C2302: Risk-On | D2302: 0 | E2302: Regime 1 | F2302: FALSE | G2302: Neutral | H2302: Underweight | I2302: Overweight | J2302: Overweight | K2302: 45-55% | L2302: 10-20% | M2302: 25-35% | N2302: 8-15% | O2302: None | P2302: Real Yield Tightening is OFF; base Portfolio Router stance is unchanged. Final stance matches base Portfolio Router stance.
A2303: 38758 | B2303: TRUE | C2303: Risk-On | D2303: 0 | E2303: Regime 1 | F2303: TRUE | G2303: Neutral | H2303: Underweight | I2303: Overweight | J2303: Overweight | K2303: 45-55% | L2303: 10-20% | M2303: 25-35% | N2303: 8-15% | O2303: None | P2303: Real Yield Tightening is ON, but no Equity or Duration Overweight stance needed to be capped. Final stance matches base Portfolio Router stance.
A2304: 38765 | B2304: TRUE | C2304: Risk-On | D2304: 0 | E2304: Regime 1 | F2304: TRUE | G2304: Neutral | H2304: Underweight | I2304: Overweight | J2304: Overweight | K2304: 45-55% | L2304: 10-20% | M2304: 25-35% | N2304: 8-15% | O2304: None | P2304: Real Yield Tightening is ON, but no Equity or Duration Overweight stance needed to be capped. Final stance matches base Portfolio Router stance.
A2305: 38772 | B2305: TRUE | C2305: Risk-On | D2305: 0 | E2305: Regime 1 | F2305: FALSE | G2305: Neutral | H2305: Underweight | I2305: Overweight | J2305: Overweight | K2305: 45-55% | L2305: 10-20% | M2305: 25-35% | N2305: 8-15% | O2305: None | P2305: Real Yield Tightening is OFF; base Portfolio Router stance is unchanged. Final stance matches base Portfolio Router stance.
A2306: 38779 | B2306: TRUE | C2306: Risk-On | D2306: 0 | E2306: Regime 1 | F2306: TRUE | G2306: Neutral | H2306: Underweight | I2306: Overweight | J2306: Overweight | K2306: 45-55% | L2306: 10-20% | M2306: 25-35% | N2306: 8-15% | O2306: None | P2306: Real Yield Tightening is ON, but no Equity or Duration Overweight stance needed to be capped. Final stance matches base Portfolio Router stance.
A2307: 38786 | B2307: TRUE | C2307: Risk-On | D2307: 0 | E2307: Regime 1 | F2307: TRUE | G2307: Neutral | H2307: Underweight | I2307: Overweight | J2307: Overweight | K2307: 45-55% | L2307: 10-20% | M2307: 25-35% | N2307: 8-15% | O2307: None | P2307: Real Yield Tightening is ON, but no Equity or Duration Overweight stance needed to be capped. Final stance matches base Portfolio Router stance.
... A3381: 46304 | B3381: TRUE | C3381: Neutral | D3381: 2 | E3381: Regime 2 | F3381: TRUE | G3381: Neutral | H3381: Neutral | I3381: Overweight | J3381: Neutral | K3381: 45-55% | L3381: 25-35% | M3381: 25-35% | N3381: 3-7% | O3381: None | P3381: Real Yield Tightening is ON, but no Equity or Duration Overweight stance needed to be capped. Final stance matches base Portfolio Router stance.

Sheet Risk Appetite
A1: As-of Date | B1: Risk Appetite Valid | C1: Risk Appetite Regime | D1: Risk Appetite Score | E1: Credit_Flag | F1: HY_Reason | G1: NFCI_Flag | H1: VIX_Flag | I1: Claims_Flag | J1: Risk Appetite Trend | K1: Next Risk Appetite Trigger
A2: 22651 | B2: FALSE | C2: Insufficient Data | F2: Insufficient Data | J2: Insufficient Data | K2: Insufficient data to generate Risk Appetite trigger.
A3: 22658 | B3: FALSE | C3: Insufficient Data | F3: Insufficient Data | J3: Insufficient Data | K3: Insufficient data to generate Risk Appetite trigger.
A4: 22665 | B4: FALSE | C4: Insufficient Data | F4: Insufficient Data | J4: Insufficient Data | K4: Insufficient data to generate Risk Appetite trigger.
A5: 22672 | B5: FALSE | C5: Insufficient Data | F5: Insufficient Data | J5: Insufficient Data | K5: Insufficient data to generate Risk Appetite trigger.
A6: 22679 | B6: FALSE | C6: Insufficient Data | F6: Insufficient Data | J6: Insufficient Data | K6: Insufficient data to generate Risk Appetite trigger.
A7: 22686 | B7: FALSE | C7: Insufficient Data | F7: Insufficient Data | J7: Insufficient Data | K7: Insufficient data to generate Risk Appetite trigger.
A8: 22693 | B8: FALSE | C8: Insufficient Data | F8: Insufficient Data | J8: Insufficient Data | K8: Insufficient data to generate Risk Appetite trigger.
A9: 22700 | B9: FALSE | C9: Insufficient Data | F9: Insufficient Data | J9: Insufficient Data | K9: Insufficient data to generate Risk Appetite trigger.
A10: 22707 | B10: FALSE | C10: Insufficient Data | F10: Insufficient Data | J10: Insufficient Data | K10: Insufficient data to generate Risk Appetite trigger.
A11: 22714 | B11: FALSE | C11: Insufficient Data | F11: Insufficient Data | J11: Insufficient Data | K11: Insufficient data to generate Risk Appetite trigger.
A12: 22721 | B12: FALSE | C12: Insufficient Data | F12: Insufficient Data | J12: Insufficient Data | K12: Insufficient data to generate Risk Appetite trigger.
A13: 22728 | B13: FALSE | C13: Insufficient Data | F13: Insufficient Data | J13: Insufficient Data | K13: Insufficient data to generate Risk Appetite trigger.
... A2295: 38702 | B2295: FALSE | C2295: Insufficient Data | F2295: Insufficient Data | J2295: Insufficient Data | K2295: Insufficient data to generate Risk Appetite trigger.
A2296: 38709 | B2296: TRUE | C2296: Neutral | D2296: 1 | E2296: 0 | F2296: None | G2296: 1 | H2296: 0 | I2296: 0 | J2296: Stable - insufficient prior history | K2296: If one additional stress flag turns ON and Risk Appetite score moves from 1 to 2, Risk Appetite remains Neutral but risk appetite deteriorates.
A2297: 38716 | B2297: TRUE | C2297: Neutral | D2297: 2 | E2297: 1 | F2297: Momentum | G2297: 1 | H2297: 0 | I2297: 0 | J2297: Deteriorating | K2297: If one additional stress flag turns ON and Risk Appetite score moves from 2 to 3, Risk Appetite shifts from Neutral to Risk-Off.
A2298: 38723 | B2298: TRUE | C2298: Neutral | D2298: 2 | E2298: 1 | F2298: Momentum | G2298: 1 | H2298: 0 | I2298: 0 | J2298: Deteriorating | K2298: If one additional stress flag turns ON and Risk Appetite score moves from 2 to 3, Risk Appetite shifts from Neutral to Risk-Off.
A2299: 38730 | B2299: TRUE | C2299: Risk-On | D2299: 0 | E2299: 0 | F2299: None | G2299: 0 | H2299: 0 | I2299: 0 | J2299: Improving | K2299: If any stress flag turns ON and Risk Appetite score moves from 0 to 1, Risk Appetite shifts from Risk-On to Neutral.
A2300: 38737 | B2300: TRUE | C2300: Neutral | D2300: 1 | E2300: 0 | F2300: None | G2300: 0 | H2300: 1 | I2300: 0 | J2300: Deteriorating | K2300: If one additional stress flag turns ON and Risk Appetite score moves from 1 to 2, Risk Appetite remains Neutral but risk appetite deteriorates.
A2301: 38744 | B2301: TRUE | C2301: Risk-On | D2301: 0 | E2301: 0 | F2301: None | G2301: 0 | H2301: 0 | I2301: 0 | J2301: Improving | K2301: If any stress flag turns ON and Risk Appetite score moves from 0 to 1, Risk Appetite shifts from Risk-On to Neutral.
A2302: 38751 | B2302: TRUE | C2302: Risk-On | D2302: 0 | E2302: 0 | F2302: None | G2302: 0 | H2302: 0 | I2302: 0 | J2302: Stable | K2302: If any stress flag turns ON and Risk Appetite score moves from 0 to 1, Risk Appetite shifts from Risk-On to Neutral.
A2303: 38758 | B2303: TRUE | C2303: Risk-On | D2303: 0 | E2303: 0 | F2303: None | G2303: 0 | H2303: 0 | I2303: 0 | J2303: Stable | K2303: If any stress flag turns ON and Risk Appetite score moves from 0 to 1, Risk Appetite shifts from Risk-On to Neutral.
A2304: 38765 | B2304: TRUE | C2304: Risk-On | D2304: 0 | E2304: 0 | F2304: None | G2304: 0 | H2304: 0 | I2304: 0 | J2304: Stable | K2304: If any stress flag turns ON and Risk Appetite score moves from 0 to 1, Risk Appetite shifts from Risk-On to Neutral.
A2305: 38772 | B2305: TRUE | C2305: Risk-On | D2305: 0 | E2305: 0 | F2305: None | G2305: 0 | H2305: 0 | I2305: 0 | J2305: Stable | K2305: If any stress flag turns ON and Risk Appetite score moves from 0 to 1, Risk Appetite shifts from Risk-On to Neutral.
A2306: 38779 | B2306: TRUE | C2306: Risk-On | D2306: 0 | E2306: 0 | F2306: None | G2306: 0 | H2306: 0 | I2306: 0 | J2306: Stable | K2306: If any stress flag turns ON and Risk Appetite score moves from 0 to 1, Risk Appetite shifts from Risk-On to Neutral.
A2307: 38786 | B2307: TRUE | C2307: Risk-On | D2307: 0 | E2307: 0 | F2307: None | G2307: 0 | H2307: 0 | I2307: 0 | J2307: Stable | K2307: If any stress flag turns ON and Risk Appetite score moves from 0 to 1, Risk Appetite shifts from Risk-On to Neutral.
... A3381: 46304 | B3381: TRUE | C3381: Neutral | D3381: 2 | E3381: 1 | F3381: Both | G3381: 1 | H3381: 0 | I3381: 0 | J3381: Deteriorating | K3381: If one additional stress flag turns ON and Risk Appetite score moves from 2 to 3, Risk Appetite shifts from Neutral to Risk-Off.

Sheet Rates & Inflation
A1: As-of Date | B1: Rates & Inflation Valid | C1: Rates & Inflation Regime | D1: Rate_Pressure | E1: Rate_Reason | F1: Inflation_Concern | G1: Inflation_Reason | H1: Real_Yield_Tightening | I1: Real_Yield_Reason | J1: Next Rates & Inflation Trigger | K1: Real_Yield_Trigger
A2: 22651 | B2: FALSE | C2: Insufficient Data | E2: Insufficient Data | G2: Insufficient Data | I2: Insufficient Data | J2: Insufficient data to generate Rates & Inflation trigger. | K2: Insufficient data to generate Real Yield trigger.
A3: 22658 | B3: FALSE | C3: Insufficient Data | E3: Insufficient Data | G3: Insufficient Data | I3: Insufficient Data | J3: Insufficient data to generate Rates & Inflation trigger. | K3: Insufficient data to generate Real Yield trigger.
A4: 22665 | B4: FALSE | C4: Insufficient Data | E4: Insufficient Data | G4: Insufficient Data | I4: Insufficient Data | J4: Insufficient data to generate Rates & Inflation trigger. | K4: Insufficient data to generate Real Yield trigger.
A5: 22672 | B5: FALSE | C5: Insufficient Data | E5: Insufficient Data | G5: Insufficient Data | I5: Insufficient Data | J5: Insufficient data to generate Rates & Inflation trigger. | K5: Insufficient data to generate Real Yield trigger.
A6: 22679 | B6: FALSE | C6: Insufficient Data | E6: Insufficient Data | G6: Insufficient Data | I6: Insufficient Data | J6: Insufficient data to generate Rates & Inflation trigger. | K6: Insufficient data to generate Real Yield trigger.
A7: 22686 | B7: FALSE | C7: Insufficient Data | E7: Insufficient Data | G7: Insufficient Data | I7: Insufficient Data | J7: Insufficient data to generate Rates & Inflation trigger. | K7: Insufficient data to generate Real Yield trigger.
A8: 22693 | B8: FALSE | C8: Insufficient Data | E8: Insufficient Data | G8: Insufficient Data | I8: Insufficient Data | J8: Insufficient data to generate Rates & Inflation trigger. | K8: Insufficient data to generate Real Yield trigger.
A9: 22700 | B9: FALSE | C9: Insufficient Data | E9: Insufficient Data | G9: Insufficient Data | I9: Insufficient Data | J9: Insufficient data to generate Rates & Inflation trigger. | K9: Insufficient data to generate Real Yield trigger.
A10: 22707 | B10: FALSE | C10: Insufficient Data | E10: Insufficient Data | G10: Insufficient Data | I10: Insufficient Data | J10: Insufficient data to generate Rates & Inflation trigger. | K10: Insufficient data to generate Real Yield trigger.
A11: 22714 | B11: FALSE | C11: Insufficient Data | E11: Insufficient Data | G11: Insufficient Data | I11: Insufficient Data | J11: Insufficient data to generate Rates & Inflation trigger. | K11: Insufficient data to generate Real Yield trigger.
A12: 22721 | B12: FALSE | C12: Insufficient Data | E12: Insufficient Data | G12: Insufficient Data | I12: Insufficient Data | J12: Insufficient data to generate Rates & Inflation trigger. | K12: Insufficient data to generate Real Yield trigger.
A13: 22728 | B13: FALSE | C13: Insufficient Data | E13: Insufficient Data | G13: Insufficient Data | I13: Insufficient Data | J13: Insufficient data to generate Rates & Inflation trigger. | K13: Insufficient data to generate Real Yield trigger.
... A2191: 37974 | B2191: FALSE | C2191: Insufficient Data | E2191: Insufficient Data | G2191: Insufficient Data | I2191: Insufficient Data | J2191: Insufficient data to generate Rates & Inflation trigger. | K2191: Insufficient data to generate Real Yield trigger.
A2192: 37981 | B2192: TRUE | C2192: Regime 3 | D2192: FALSE | E2192: None | F2192: TRUE | G2192: Level | H2192: FALSE | I2192: None | J2192: If DGS10 crosses P80 or 4W Change turns positive, Rate Pressure turns ON and Rates & Inflation shifts from Regime 3 to Regime 1. | K2192: If DFII10 crosses P80 or 4W Change turns positive, Real Yield Tightening turns ON and aggressive Equity Overweight and Duration Overweight positions are capped.
A2193: 37988 | B2193: TRUE | C2193: Regime 1 | D2193: TRUE | E2193: Both | F2193: TRUE | G2193: Both | H2193: TRUE | I2193: Momentum | J2193: If either Rate Pressure or Inflation Concern turns OFF, Rates & Inflation shifts out of Regime 1. | K2193: If Real Yield Tightening remains ON, aggressive Equity Overweight and Duration Overweight positions are capped.
A2194: 37995 | B2194: TRUE | C2194: Regime 4 | D2194: FALSE | E2194: None | F2194: FALSE | G2194: None | H2194: FALSE | I2194: None | J2194: If DGS10 or T10YIE crosses P80 or 4W Change turns positive, Rates & Inflation shifts to a pressure regime. | K2194: If DFII10 crosses P80 or 4W Change turns positive, Real Yield Tightening turns ON and aggressive Equity Overweight and Duration Overweight positions are capped.
A2195: 38002 | B2195: TRUE | C2195: Regime 3 | D2195: FALSE | E2195: None | F2195: TRUE | G2195: Momentum | H2195: FALSE | I2195: None | J2195: If DGS10 crosses P80 or 4W Change turns positive, Rate Pressure turns ON and Rates & Inflation shifts from Regime 3 to Regime 1. | K2195: If DFII10 crosses P80 or 4W Change turns positive, Real Yield Tightening turns ON and aggressive Equity Overweight and Duration Overweight positions are capped.
A2196: 38009 | B2196: TRUE | C2196: Regime 3 | D2196: FALSE | E2196: None | F2196: TRUE | G2196: Both | H2196: FALSE | I2196: None | J2196: If DGS10 crosses P80 or 4W Change turns positive, Rate Pressure turns ON and Rates & Inflation shifts from Regime 3 to Regime 1. | K2196: If DFII10 crosses P80 or 4W Change turns positive, Real Yield Tightening turns ON and aggressive Equity Overweight and Duration Overweight positions are capped.
A2197: 38016 | B2197: TRUE | C2197: Regime 3 | D2197: FALSE | E2197: None | F2197: TRUE | G2197: Level | H2197: FALSE | I2197: None | J2197: If DGS10 crosses P80 or 4W Change turns positive, Rate Pressure turns ON and Rates & Inflation shifts from Regime 3 to Regime 1. | K2197: If DFII10 crosses P80 or 4W Change turns positive, Real Yield Tightening turns ON and aggressive Equity Overweight and Duration Overweight positions are capped.
A2198: 38023 | B2198: TRUE | C2198: Regime 1 | D2198: TRUE | E2198: Momentum | F2198: TRUE | G2198: Both | H2198: FALSE | I2198: None | J2198: If either Rate Pressure or Inflation Concern turns OFF, Rates & Inflation shifts out of Regime 1. | K2198: If DFII10 crosses P80 or 4W Change turns positive, Real Yield Tightening turns ON and aggressive Equity Overweight and Duration Overweight positions are capped.
A2199: 38030 | B2199: TRUE | C2199: Regime 1 | D2199: TRUE | E2199: Momentum | F2199: TRUE | G2199: Both | H2199: FALSE | I2199: None | J2199: If either Rate Pressure or Inflation Concern turns OFF, Rates & Inflation shifts out of Regime 1. | K2199: If DFII10 crosses P80 or 4W Change turns positive, Real Yield Tightening turns ON and aggressive Equity Overweight and Duration Overweight positions are capped.
A2200: 38037 | B2200: TRUE | C2200: Regime 1 | D2200: TRUE | E2200: Momentum | F2200: TRUE | G2200: Momentum | H2200: FALSE | I2200: None | J2200: If either Rate Pressure or Inflation Concern turns OFF, Rates & Inflation shifts out of Regime 1. | K2200: If DFII10 crosses P80 or 4W Change turns positive, Real Yield Tightening turns ON and aggressive Equity Overweight and Duration Overweight positions are capped.
A2201: 38044 | B2201: TRUE | C2201: Regime 3 | D2201: FALSE | E2201: None | F2201: TRUE | G2201: Both | H2201: FALSE | I2201: None | J2201: If DGS10 crosses P80 or 4W Change turns positive, Rate Pressure turns ON and Rates & Inflation shifts from Regime 3 to Regime 1. | K2201: If DFII10 crosses P80 or 4W Change turns positive, Real Yield Tightening turns ON and aggressive Equity Overweight and Duration Overweight positions are capped.
A2202: 38051 | B2202: TRUE | C2202: Regime 3 | D2202: FALSE | E2202: None | F2202: TRUE | G2202: Both | H2202: FALSE | I2202: None | J2202: If DGS10 crosses P80 or 4W Change turns positive, Rate Pressure turns ON and Rates & Inflation shifts from Regime 3 to Regime 1. | K2202: If DFII10 crosses P80 or 4W Change turns positive, Real Yield Tightening turns ON and aggressive Equity Overweight and Duration Overweight positions are capped.
A2203: 38058 | B2203: TRUE | C2203: Regime 4 | D2203: FALSE | E2203: None | F2203: FALSE | G2203: None | H2203: FALSE | I2203: None | J2203: If DGS10 or T10YIE crosses P80 or 4W Change turns positive, Rates & Inflation shifts to a pressure regime. | K2203: If DFII10 crosses P80 or 4W Change turns positive, Real Yield Tightening turns ON and aggressive Equity Overweight and Duration Overweight positions are capped.
... A3381: 46304 | B3381: TRUE | C3381: Regime 2 | D3381: TRUE | E3381: Both | F3381: FALSE | G3381: None | H3381: TRUE | I3381: Both | J3381: If T10YIE crosses P80 or 4W Change turns positive, Inflation Concern turns ON and Rates & Inflation shifts from Regime 2 to Regime 1. | K3381: If Real Yield Tightening remains ON, aggressive Equity Overweight and Duration Overweight positions are capped.

Sheet Stress Event Audit
A1: Event | B1: Window Start | C1: Window End | D1: Stress Type | E1: Expected Response | F1: First Warning Rule | G1: Framework Valid | H1: Pre-Event Risk Appetite Regime | I1: Pre-Event Rates & Inflation Regime | J1: Pre_Equity_Stance | K1: Pre_Cash_Stance | L1: Pre-Existing Stress at Window Start | M1: First Warning Date | N1: Recognition Timing | O1: Peak Stress Date | P1: Peak Risk Appetite Regime | Q1: Peak Risk Appetite Score | R1: Peak Rates & Inflation Regime | S1: Peak_Equity_Stance | T1: Peak_Cash_Stance | U1: Peak Drivers | V1: Real Yield Tightening Seen in Window | W1: Real Yield Tightening at Peak | X1: Diagnostic Result | Y1: Diagnostic Note
A2: Global Financial Crisis | B2: 39264 | C2: 39994 | D2: Credit / Financial Conditions / Labor | E2: Risk Appetite should deteriorate materially, ideally reaching Risk-Off during peak stress. Portfolio Router should reduce equity risk and increase defensive positioning. | F2: Risk Appetite Score >= 1 | G2: Yes | H2: Risk-Off | I2: Regime 2 | J2: Underweight | K2: Overweight | L2: Yes | M2: Pre-existing | N2: 0 | O2: 39325 | P2: Risk-Off | Q2: 4 | R2: Regime 4 | S2: Underweight | T2: Overweight | U2: Credit, Financial Conditions, Volatility, Labor | V2: Yes | W2: No | X2: Recognized | Y2: Framework was already stressed before the event window (Yes). Peak Risk Appetite=Risk-Off (score 4), Rates & Inflation=Regime 4, Equity=Underweight, Cash=Overweight. Peak drivers: Credit, Financial Conditions, Volatility, Labor. Real Yield Tightening appeared during the window. Real Yield Tightening was OFF at peak. Miss status: No Miss.
A3: 2011 Eurozone / US Debt Ceiling Stress | B3: 40725 | C3: 40847 | D3: Volatility / Credit / Policy | E3: Risk Appetite should show at least Neutral or elevated volatility/credit stress. | F3: Risk Appetite Score >= 1 | G3: Yes | H3: Neutral | I3: Regime 4 | J3: Neutral | K3: Neutral | L3: Partial | M3: Pre-existing | N3: 0 | O3: 40760 | P3: Risk-Off | Q3: 3 | R3: Regime 4 | S3: Underweight | T3: Overweight | U3: Credit, Financial Conditions, Volatility | V3: Yes | W3: No | X3: Recognized | Y3: Framework was already stressed before the event window (Partial). Peak Risk Appetite=Risk-Off (score 3), Rates & Inflation=Regime 4, Equity=Underweight, Cash=Overweight. Peak drivers: Credit, Financial Conditions, Volatility. Real Yield Tightening appeared during the window. Real Yield Tightening was OFF at peak. Miss status: No Miss.
A4: 2015-2016 China / Oil / HY Stress | B4: 42217 | C4: 42429 | D4: Credit / Growth / Commodity | E4: HY OAS and broader risk appetite indicators should help Risk Appetite deteriorate or at least move to Neutral. | F4: Risk Appetite Score >= 1 | G4: Yes | H4: Neutral | I4: Regime 4 | J4: Neutral | K4: Neutral | L4: Partial | M4: Pre-existing | N4: 0 | O4: 42391 | P4: Risk-Off | Q4: 4 | R4: Regime 4 | S4: Underweight | T4: Overweight | U4: Credit, Financial Conditions, Volatility, Labor, Real Yield Tightening | V4: Yes | W4: Yes | X4: Recognized | Y4: Framework was already stressed before the event window (Partial). Peak Risk Appetite=Risk-Off (score 4), Rates & Inflation=Regime 4, Equity=Underweight, Cash=Overweight. Peak drivers: Credit, Financial Conditions, Volatility, Labor, Real Yield Tightening. Real Yield Tightening appeared during the window. Real Yield Tightening was ON at peak. Miss status: No Miss.
A5: 2018 Volmageddon / Q4 Selloff | B5: 43132 | C5: 43465 | D5: Volatility / Rates / Risk Appetite | E5: Risk Appetite should show volatility or risk-appetite deterioration around the February volatility spike and/or Q4 selloff. | F5: Risk Appetite Score >= 1 | G5: Yes | H5: Risk-On | I5: Regime 1 | J5: Neutral | K5: Overweight | L5: No | M5: 43133 | N5: 0.1 | O5: 43441 | P5: Risk-Off | Q5: 4 | R5: Regime 4 | S5: Underweight | T5: Overweight | U5: Credit, Financial Conditions, Volatility, Labor, Real Yield Tightening | V5: Yes | W5: Yes | X5: Recognized | Y5: First warning appeared on 2018-02-02 after 0.1 weeks. Peak Risk Appetite=Risk-Off (score 4), Rates & Inflation=Regime 4, Equity=Underweight, Cash=Overweight. Peak drivers: Credit, Financial Conditions, Volatility, Labor, Real Yield Tightening. Real Yield Tightening appeared during the window. Real Yield Tightening was ON at peak. Miss status: No Miss.
A6: COVID Shock | B6: 43862 | C6: 43951 | D6: Fast Volatility / Credit / Labor Shock | E6: Risk Appetite should deteriorate rapidly due to volatility, credit, financial conditions, and labor stress. Portfolio Router should move defensively. | F6: Risk Appetite Score >= 1 | G6: Yes | H6: Neutral | I6: Regime 4 | J6: Neutral | K6: Neutral | L6: Partial | M6: Pre-existing | N6: 0 | O6: 43910 | P6: Risk-Off | Q6: 4 | R6: Regime 4 | S6: Underweight | T6: Overweight | U6: Credit, Financial Conditions, Volatility, Labor, Real Yield Tightening | V6: Yes | W6: Yes | X6: Recognized | Y6: Framework was already stressed before the event window (Partial). Peak Risk Appetite=Risk-Off (score 4), Rates & Inflation=Regime 4, Equity=Underweight, Cash=Overweight. Peak drivers: Credit, Financial Conditions, Volatility, Labor, Real Yield Tightening. Real Yield Tightening appeared during the window. Real Yield Tightening was ON at peak. Miss status: No Miss.
A7: 2022 Inflation / Rates Shock | B7: 44562 | C7: 44926 | D7: Rates / Inflation / Real Yield | E7: Rates & Inflation should show Rate Pressure and/or Inflation Concern. Real Yield Tightening should cap aggressive Equity OW and Duration OW. | F7: Rate_Pressure ON or Inflation_Concern ON or Real_Yield_Tightening ON | G7: Yes | H7: Neutral | I7: Regime 1 | J7: Underweight | K7: Overweight | L7: Yes | M7: Pre-existing | N7: 0 | O7: 44568 | P7: Neutral | Q7: 1 | R7: Regime 1 | S7: Underweight | T7: Overweight | U7: Financial Conditions, Rate Pressure, Inflation Concern, Real Yield Tightening | V7: Yes | W7: Yes | X7: Recognized | Y7: Framework was already stressed before the event window (Yes). Peak Risk Appetite=Neutral (score 1), Rates & Inflation=Regime 1, Equity=Underweight, Cash=Overweight. Peak drivers: Financial Conditions, Rate Pressure, Inflation Concern, Real Yield Tightening. Real Yield Tightening appeared during the window. Real Yield Tightening was ON at peak. Miss status: No Miss.
A8: 2023 Regional Bank Stress | B8: 44986 | C8: 45077 | D8: Banking / Financial Conditions / Rates | E8: Risk Appetite should show some deterioration through financial conditions, volatility, or credit, but full Risk-Off may not be necessary if the shock is contained. | F8: Risk Appetite Score >= 1 | G8: Yes | H8: Neutral | I8: Regime 1 | J8: Underweight | K8: Overweight | L8: Partial | M8: Pre-existing | N8: 0 | O8: 45009 | P8: Risk-Off | Q8: 3 | R8: Regime 4 | S8: Underweight | T8: Overweight | U8: Credit, Financial Conditions, Labor | V8: Yes | W8: No | X8: Recognized | Y8: Framework was already stressed before the event window (Partial). Peak Risk Appetite=Risk-Off (score 3), Rates & Inflation=Regime 4, Equity=Underweight, Cash=Overweight. Peak drivers: Credit, Financial Conditions, Labor. Real Yield Tightening appeared during the window. Real Yield Tightening was OFF at peak. Miss status: No Miss.

Sheet Regime Co-occurrence
A1: Regime Co-occurrence | B1: Regime 1 | C1: Regime 2 | D1: Regime 3 | E1: Regime 4 | F1: Total
A2: Risk-On | B2: 0.21362799 | C2: 0.063535912 | D2: 0.066298343 | E2: 0.064456722 | F2: 0.40791897
A3: Neutral | B3: 0.14917127 | C3: 0.067219153 | D3: 0.072744015 | E3: 0.14364641 | F3: 0.43278085
A4: Risk-Off | B4: 0.031307551 | C4: 0.027624309 | D4: 0.023020258 | E4: 0.077348066 | F4: 0.15930018
A5: Total | B5: 0.39410681 | C5: 0.15837937 | D5: 0.16206262 | E5: 0.2854512 | F5: 1

Sheet Data Quality
A1: Check | B1: Status | C1: Details
A2: Missing Latest Value | B2: PASS | C2: No missing values in latest row on 2026-10-09.
A3: Series Freshness | B3: PASS | C3: All tracked series are fresh as of 2026-10-09.
A4: Rolling Window Sufficiency | B4: PASS | C4: All required Risk Appetite / Rates & Inflation series have at least 52 non-null weekly observations as of 2026-10-09. hy_oas: PASS; nfci: PASS; vix: PASS; claims: PASS; dgs10: PASS; t10yie: PASS; dfii10: PASS.
A5: As-of Date Alignment | B5: PASS | C5: Risk Appetite and Rates & Inflation As-of Date indexes match through 2026-10-09.
A6: Portfolio Router Output Available | B6: PASS | C6: Portfolio Router output is available through 2026-10-09.
A7: Latest Signal Validity | B7: PASS | C7: Latest Risk Appetite, Rates & Inflation, and Portfolio Router outputs are valid as of 2026-10-09.

Sheet _DASH_DATA
A1: Metric | B1: Value | D1: Date | E1: Risk Appetite Score | F1: Risk Appetite Risk-On / Neutral Boundary | G1: Risk Appetite Neutral / Risk-Off Boundary | H1: Latest Risk Appetite Score | I1: Risk Appetite Regime Code | K1: Date | L1: Rates & Inflation Regime Code | M1: Latest Rates & Inflation Regime Code | N1: Rate Pressure Binary | O1: Inflation Concern Binary | Q1: Date | R1: DGS10 | S1: DGS10 52W P80 Threshold | T1: DGS10 52W P20 Context Band | U1: Latest DGS10 | V1: DGS10 4W Change | X1: Date | Y1: T10YIE | Z1: T10YIE 52W P80 Threshold | AA1: T10YIE 52W P20 Context Band | AB1: Latest T10YIE | AC1: T10YIE 4W Change | AE1: Date | AF1: DFII10 | AG1: DFII10 52W P80 Threshold | AH1: DFII10 52W P20 Context Band | AI1: Latest DFII10 | AJ1: DFII10 4W Change | AL1: Date | AM1: 10Y-2Y Curve Slope | AN1: Zero Line | AO1: Latest 10Y-2Y Curve Slope | AQ1: Event | AR1: Diagnostic Result | AS1: Response Lag (Weeks) | AT1: Peak Risk Appetite Regime | AU1: Peak Rates & Inflation Regime | AV1: Peak Drivers | AW1: Pre-Existing Stress at Window Start
A2: As of Date | B2: 46304 | D2: 45583 | E2: 2 | F2: 0.5 | G2: 2.5 | I2: 1 | K2: 45583 | L2: 1 | N2: 1 | O2: 1 | Q2: 44491 | R2: 1.66 | S2: 1.598 | T2: 1.102 | V2: 0.19 | X2: 44491 | Y2: 2.64 | Z2: 2.398 | AA2: 2.066 | AC2: 0.3 | AE2: 44491 | AF2: -0.98 | AG2: -0.792 | AH2: -1.018 | AJ2: -0.11 | AL2: 44491 | AM2: 1.18 | AN2: 0 | AQ2: Global Financial Crisis | AR2: Recognized | AT2: Risk-Off | AU2: Regime 4 | AV2: Credit, Financial Conditions, Volatility, Labor | AW2: Yes
A3: Risk Appetite Regime | B3: Neutral | D3: 45590 | E3: 1 | F3: 0.5 | G3: 2.5 | I3: 1 | K3: 45590 | L3: 1 | N3: 1 | O3: 1 | Q3: 44498 | R3: 1.55 | S3: 1.598 | T3: 1.11 | V3: 0.07 | X3: 44498 | Y3: 2.51 | Z3: 2.4 | AA3: 2.092 | AC3: 0.13 | AE3: 44498 | AF3: -0.96 | AG3: -0.792 | AH3: -1.018 | AJ3: -0.06 | AL3: 44498 | AM3: 1.07 | AN3: 0 | AQ3: 2011 Eurozone / US Debt Ceiling Stress | AR3: Recognized | AT3: Risk-Off | AU3: Regime 4 | AV3: Credit, Financial Conditions, Volatility | AW3: Partial
A4: Risk Appetite Score | B4: 2 | D4: 45597 | E4: 1 | F4: 0.5 | G4: 2.5 | I4: 1 | K4: 45597 | L4: 1 | N4: 1 | O4: 1 | Q4: 44505 | R4: 1.45 | S4: 1.598 | T4: 1.114 | V4: -0.16 | X4: 44505 | Y4: 2.54 | Z4: 2.4 | AA4: 2.106 | AC4: 0.04 | AE4: 44505 | AF4: -1.09 | AG4: -0.792 | AH4: -1.02 | AJ4: -0.2 | AL4: 44505 | AM4: 1.06 | AN4: 0 | AQ4: 2015-2016 China / Oil / HY Stress | AR4: Recognized | AT4: Risk-Off | AU4: Regime 4 | AV4: Credit, Financial Conditions, Volatility, Labor, Real Yield Tightening | AW4: Partial
A5: Risk Appetite Trend | B5: Deteriorating | D5: 45604 | E5: 0 | F5: 0.5 | G5: 2.5 | I5: 0 | K5: 45604 | L5: 1 | N5: 1 | O5: 1 | Q5: 44512 | R5: 1.58 | S5: 1.598 | T5: 1.142 | V5: -0.01 | X5: 44512 | Y5: 2.73 | Z5: 2.408 | AA5: 2.132 | AC5: 0.17 | AE5: 44512 | AF5: -1.15 | AG5: -0.792 | AH5: -1.02 | AJ5: -0.18 | AL5: 44512 | AM5: 1.05 | AN5: 0 | AQ5: 2018 Volmageddon / Q4 Selloff | AR5: Recognized | AT5: Risk-Off | AU5: Regime 4 | AV5: Credit, Financial Conditions, Volatility, Labor, Real Yield Tightening | AW5: No
A6: Rates & Inflation Regime | B6: Regime 2 | D6: 45611 | E6: 0 | F6: 0.5 | G6: 2.5 | I6: 0 | K6: 45611 | L6: 1 | N6: 1 | O6: 1 | Q6: 44519 | R6: 1.54 | S6: 1.598 | T6: 1.192 | V6: -0.12 | X6: 44519 | Y6: 2.65 | Z6: 2.418 | AA6: 2.142 | AC6: 0.01 | AE6: 44519 | AF6: -1.11 | AG6: -0.792 | AH6: -1.028 | AJ6: -0.13 | AL6: 44519 | AM6: 1.02 | AN6: 0 | AQ6: COVID Shock | AR6: Recognized | AT6: Risk-Off | AU6: Regime 4 | AV6: Credit, Financial Conditions, Volatility, Labor, Real Yield Tightening | AW6: Partial
A7: Rate Pressure | B7: TRUE | D7: 45618 | E7: 0 | F7: 0.5 | G7: 2.5 | I7: 0 | K7: 45618 | L7: 1 | N7: 1 | O7: 1 | Q7: 44526 | R7: 1.48 | S7: 1.598 | T7: 1.208 | V7: -0.07 | X7: 44526 | Y7: 2.55 | Z7: 2.428 | AA7: 2.162 | AC7: 0.04 | AE7: 44526 | AF7: -1.07 | AG7: -0.792 | AH7: -1.046 | AJ7: -0.11 | AL7: 44526 | AM7: 0.98 | AN7: 0 | AQ7: 2022 Inflation / Rates Shock | AR7: Recognized | AT7: Neutral | AU7: Regime 1 | AV7: Financial Conditions, Rate Pressure, Inflation Concern, Real Yield Tightening | AW7: Yes
A8: Inflation Concern | B8: FALSE | D8: 45625 | E8: 0 | F8: 0.5 | G8: 2.5 | I8: 0 | K8: 45625 | L8: 4 | N8: 0 | O8: 0 | Q8: 44533 | R8: 1.35 | S8: 1.598 | T8: 1.244 | V8: -0.1 | X8: 44533 | Y8: 2.43 | Z8: 2.43 | AA8: 2.21 | AC8: -0.11 | AE8: 44533 | AF8: -1.08 | AG8: -0.792 | AH8: -1.05 | AJ8: 0.01 | AL8: 44533 | AM8: 0.75 | AN8: 0 | AQ8: 2023 Regional Bank Stress | AR8: Recognized | AT8: Risk-Off | AU8: Regime 4 | AV8: Credit, Financial Conditions, Labor | AW8: Partial
A9: Real Yield Tightening | B9: ON | D9: 45632 | E9: 1 | F9: 0.5 | G9: 2.5 | I9: 1 | K9: 45632 | L9: 4 | N9: 0 | O9: 0 | Q9: 44540 | R9: 1.48 | S9: 1.598 | T9: 1.266 | V9: -0.1 | X9: 44540 | Y9: 2.44 | Z9: 2.438 | AA9: 2.212 | AC9: -0.29 | AE9: 44540 | AF9: -0.96 | AG9: -0.792 | AH9: -1.05 | AJ9: 0.19 | AL9: 44540 | AM9: 0.81 | AN9: 0
A10: Data Confidence | D10: 45639 | E10: 1 | F10: 0.5 | G10: 2.5 | I10: 1 | K10: 45639 | L10: 4 | N10: 0 | O10: 0 | Q10: 44547 | R10: 1.41 | S10: 1.598 | T10: 1.292 | V10: -0.13 | X10: 44547 | Y10: 2.38 | Z10: 2.438 | AA10: 2.224 | AC10: -0.27 | AE10: 44547 | AF10: -0.97 | AG10: -0.792 | AH10: -1.05 | AJ10: 0.14 | AL10: 44547 | AM10: 0.75 | AN10: 0
A11: Equity Stance | B11: Neutral | D11: 45646 | E11: 2 | F11: 0.5 | G11: 2.5 | I11: 1 | K11: 45646 | L11: 2 | N11: 1 | O11: 0 | Q11: 44554 | R11: 1.5 | S11: 1.598 | T11: 1.302 | V11: 0.02 | X11: 44554 | Y11: 2.47 | Z11: 2.464 | AA11: 2.244 | AC11: -0.08 | AE11: 44554 | AF11: -0.97 | AG11: -0.792 | AH11: -1.05 | AJ11: 0.1 | AL11: 44554 | AM11: 0.79 | AN11: 0
D12: 45653 | E12: 1 | F12: 0.5 | G12: 2.5 | I12: 1 | K12: 45653 | L12: 1 | N12: 1 | O12: 1 | Q12: 44561 | R12: 1.52 | S12: 1.598 | T12: 1.31 | V12: 0.17 | X12: 44561 | Y12: 2.56 | Z12: 2.486 | AA12: 2.262 | AC12: 0.13 | AE12: 44561 | AF12: -1.04 | AG12: -0.792 | AH12: -1.048 | AJ12: 0.04 | AL12: 44561 | AM12: 0.79 | AN12: 0
A13: Duration Stance | B13: Neutral | D13: 45660 | E13: 1 | F13: 0.5 | G13: 2.5 | I13: 1 | K13: 45660 | L13: 1 | N13: 1 | O13: 1 | Q13: 44568 | R13: 1.76 | S13: 1.608 | T13: 1.31 | V13: 0.28 | X13: 44568 | Y13: 2.48 | Z13: 2.488 | AA13: 2.272 | AC13: 0.04 | AE13: 44568 | AF13: -0.72 | AG13: -0.774 | AH13: -1.048 | AJ13: 0.24 | AL13: 44568 | AM13: 0.89 | AN13: 0
D14: 45667 | E14: 2 | F14: 0.5 | G14: 2.5 | I14: 1 | K14: 45667 | L14: 1 | N14: 1 | O14: 1 | Q14: 44575 | R14: 1.78 | S14: 1.626 | T14: 1.314 | V14: 0.37 | X14: 44575 | Y14: 2.44 | Z14: 2.488 | AA14: 2.286 | AC14: 0.06 | AE14: 44575 | AF14: -0.66 | AG14: -0.762 | AH14: -1.048 | AJ14: 0.31 | AL14: 44575 | AM14: 0.79 | AN14: 0
A15: Cash Stance | B15: Overweight | D15: 45674 | E15: 0 | F15: 0.5 | G15: 2.5 | I15: 0 | K15: 45674 | L15: 1 | N15: 1 | O15: 1 | Q15: 44582 | R15: 1.75 | S15: 1.63 | T15: 1.332 | V15: 0.25 | X15: 44582 | Y15: 2.34 | Z15: 2.488 | AA15: 2.31 | AC15: -0.13 | AE15: 44582 | AF15: -0.59 | AG15: -0.76 | AH15: -1.048 | AJ15: 0.38 | AL15: 44582 | AM15: 0.74 | AN15: 0
D16: 45681 | E16: 0 | F16: 0.5 | G16: 2.5 | I16: 0 | K16: 45681 | L16: 1 | N16: 1 | O16: 1 | Q16: 44589 | R16: 1.78 | S16: 1.638 | T16: 1.342 | V16: 0.26 | X16: 44589 | Y16: 2.44 | Z16: 2.488 | AA16: 2.312 | AC16: -0.12 | AE16: 44589 | AF16: -0.66 | AG16: -0.728 | AH16: -1.048 | AJ16: 0.38 | AL16: 44589 | AM16: 0.63 | AN16: 0
A17: TIPS Stance | B17: Neutral | D17: 45688 | E17: 0 | F17: 0.5 | G17: 2.5 | I17: 0 | K17: 45688 | L17: 1 | N17: 1 | O17: 1 | Q17: 44596 | R17: 1.93 | S17: 1.648 | T17: 1.35 | V17: 0.17 | X17: 44596 | Y17: 2.41 | Z17: 2.488 | AA17: 2.322 | AC17: -0.07 | AE17: 44596 | AF17: -0.48 | AG17: -0.712 | AH17: -1.048 | AJ17: 0.24 | AL17: 44596 | AM17: 0.62 | AN17: 0
D18: 45695 | E18: 0 | F18: 0.5 | G18: 2.5 | I18: 0 | K18: 45695 | L18: 3 | N18: 0 | O18: 1 | Q18: 44603 | R18: 1.92 | S18: 1.658 | T18: 1.354 | V18: 0.14 | X18: 44603 | Y18: 2.43 | Z18: 2.488 | AA18: 2.33 | AC18: -0.01 | AE18: 44603 | AF18: -0.51 | AG18: -0.678 | AH18: -1.048 | AJ18: 0.15 | AL18: 44603 | AM18: 0.42 | AN18: 0
A19: Data Quality Summary | B19: PASS: 6 | D19: 45702 | E19: 1 | F19: 0.5 | G19: 2.5 | I19: 1 | K19: 45702 | L19: 3 | N19: 0 | O19: 1 | Q19: 44610 | R19: 1.92 | S19: 1.668 | T19: 1.37 | V19: 0.17 | X19: 44610 | Y19: 2.41 | Z19: 2.488 | AA19: 2.33 | AC19: 0.07 | AE19: 44610 | AF19: -0.49 | AG19: -0.662 | AH19: -1.048 | AJ19: 0.1 | AL19: 44610 | AM19: 0.45 | AN19: 0
D20: 45709 | E20: 2 | F20: 0.5 | G20: 2.5 | I20: 1 | K20: 45709 | L20: 3 | N20: 0 | O20: 1 | Q20: 44617 | R20: 1.97 | S20: 1.67 | T20: 1.37 | V20: 0.19 | X20: 44617 | Y20: 2.54 | Z20: 2.498 | AA20: 2.332 | AC20: 0.1 | AE20: 44617 | AF20: -0.57 | AG20: -0.66 | AH20: -1.048 | AJ20: 0.09 | AL20: 44617 | AM20: 0.42 | AN20: 0
D21: 45716 | E21: 3 | F21: 0.5 | G21: 2.5 | I21: 2 | K21: 45716 | L21: 3 | N21: 0 | O21: 1 | Q21: 44624 | R21: 1.74 | S21: 1.71 | T21: 1.37 | V21: -0.19 | X21: 44624 | Y21: 2.67 | Z21: 2.508 | AA21: 2.34 | AC21: 0.26 | AE21: 44624 | AF21: -0.93 | AG21: -0.662 | AH21: -1.048 | AJ21: -0.45 | AL21: 44624 | AM21: 0.24 | AN21: 0
D22: 45723 | E22: 2 | F22: 0.5 | G22: 2.5 | I22: 1 | K22: 45723 | L22: 4 | N22: 0 | O22: 0 | Q22: 44631 | R22: 2 | S22: 1.736 | T22: 1.37 | V22: 0.08 | X22: 44631 | Y22: 2.94 | Z22: 2.51 | AA22: 2.34 | AC22: 0.51 | AE22: 44631 | AF22: -0.94 | AG22: -0.68 | AH22: -1.048 | AJ22: -0.43 | AL22: 44631 | AM22: 0.25 | AN22: 0
D23: 45730 | E23: 2 | F23: 0.5 | G23: 2.5 | I23: 1 | K23: 45730 | L23: 4 | N23: 0 | O23: 0 | Q23: 44638 | R23: 2.14 | S23: 1.736 | T23: 1.37 | V23: 0.22 | X23: 44638 | Y23: 2.86 | Z23: 2.534 | AA23: 2.34 | AC23: 0.45 | AE23: 44638 | AF23: -0.72 | AG23: -0.72 | AH23: -1.048 | AJ23: -0.23 | AL23: 44638 | AM23: 0.17 | AN23: 0
D24: 45737 | E24: 2 | F24: 0.5 | G24: 2.5 | I24: 1 | K24: 45737 | L24: 4 | N24: 0 | O24: 0 | Q24: 44645 | R24: 2.48 | S24: 1.748 | T24: 1.37 | V24: 0.51 | X24: 44645 | Y24: 2.95 | Z24: 2.54 | AA24: 2.34 | AC24: 0.41 | AE24: 44645 | AF24: -0.47 | AG24: -0.72 | AH24: -1.048 | AJ24: 0.1 | AL24: 44645 | AM24: 0.18 | AN24: 0
D25: 45744 | E25: 2 | F25: 0.5 | G25: 2.5 | I25: 1 | K25: 45744 | L25: 2 | N25: 1 | O25: 0 | Q25: 44652 | R25: 2.39 | S25: 1.758 | T25: 1.37 | V25: 0.65 | X25: 44652 | Y25: 2.8 | Z25: 2.548 | AA25: 2.34 | AC25: 0.13 | AE25: 44652 | AF25: -0.41 | AG25: -0.72 | AH25: -1.048 | AJ25: 0.52 | AL25: 44652 | AM25: -0.05 | AN25: 0
D26: 45751 | E26: 2 | F26: 0.5 | G26: 2.5 | I26: 1 | K26: 45751 | L26: 4 | N26: 0 | O26: 0 | Q26: 44659 | R26: 2.72 | S26: 1.776 | T26: 1.37 | V26: 0.72 | X26: 44659 | Y26: 2.87 | Z26: 2.558 | AA26: 2.34 | AC26: -0.07 | AE26: 44659 | AF26: -0.15 | AG26: -0.72 | AH26: -1.048 | AJ26: 0.79 | AL26: 44659 | AM26: 0.19 | AN26: 0
D27: 45758 | E27: 3 | F27: 0.5 | G27: 2.5 | I27: 2 | K27: 45758 | L27: 2 | N27: 1 | O27: 0 | Q27: 44666 | R27: 2.83 | S27: 1.78 | T27: 1.37 | V27: 0.69 | X27: 44666 | Y27: 2.89 | Z27: 2.56 | AA27: 2.34 | AC27: 0.03 | AE27: 44666 | AF27: -0.06 | AG27: -0.672 | AH27: -1.048 | AJ27: 0.66 | AL27: 44666 | AM27: 0.36 | AN27: 0
D28: 45765 | E28: 3 | F28: 0.5 | G28: 2.5 | I28: 2 | K28: 45765 | L28: 2 | N28: 1 | O28: 0 | Q28: 44673 | R28: 2.9 | S28: 1.892 | T28: 1.37 | V28: 0.42 | X28: 44673 | Y28: 2.98 | Z28: 2.624 | AA28: 2.342 | AC28: 0.03 | AE28: 44673 | AF28: -0.08 | AG28: -0.66 | AH28: -1.048 | AJ28: 0.39 | AL28: 44673 | AM28: 0.18 | AN28: 0
D29: 45772 | E29: 2 | F29: 0.5 | G29: 2.5 | I29: 1 | K29: 45772 | L29: 2 | N29: 1 | O29: 0 | Q29: 44680 | R29: 2.89 | S29: 1.92 | T29: 1.37 | V29: 0.5 | X29: 44680 | Y29: 2.88 | Z29: 2.648 | AA29: 2.342 | AC29: 0.08 | AE29: 44680 | AF29: 0.01 | AG29: -0.604 | AH29: -1.048 | AJ29: 0.42 | AL29: 44680 | AM29: 0.19 | AN29: 0
D30: 45779 | E30: 3 | F30: 0.5 | G30: 2.5 | I30: 2 | K30: 45779 | L30: 1 | N30: 1 | O30: 1 | Q30: 44687 | R30: 3.12 | S30: 1.928 | T30: 1.37 | V30: 0.4 | X30: 44687 | Y30: 2.86 | Z30: 2.666 | AA30: 2.342 | AC30: -0.01 | AE30: 44687 | AF30: 0.26 | AG30: -0.574 | AH30: -1.048 | AJ30: 0.41 | AL30: 44687 | AM30: 0.4 | AN30: 0
D31: 45786 | E31: 2 | F31: 0.5 | G31: 2.5 | I31: 1 | K31: 45786 | L31: 3 | N31: 0 | O31: 1 | Q31: 44694 | R31: 2.93 | S31: 1.962 | T31: 1.37 | V31: 0.1 | X31: 44694 | Y31: 2.69 | Z31: 2.686 | AA31: 2.342 | AC31: -0.2 | AE31: 44694 | AF31: 0.24 | AG31: -0.522 | AH31: -1.048 | AJ31: 0.3 | AL31: 44694 | AM31: 0.32 | AN31: 0
